#VRML_SIM R2025a utf8

EXTERNPROTO "https://raw.githubusercontent.com/cyberbotics/webots/R2025a/projects/objects/backgrounds/protos/TexturedBackground.proto"
EXTERNPROTO "https://raw.githubusercontent.com/cyberbotics/webots/R2025a/projects/objects/backgrounds/protos/TexturedBackgroundLight.proto"
EXTERNPROTO "https://raw.githubusercontent.com/cyberbotics/webots/R2025a/projects/objects/floors/protos/RectangleArena.proto"
EXTERNPROTO "https://raw.githubusercontent.com/cyberbotics/webots/R2025a/projects/appearances/protos/Asphalt.proto"
EXTERNPROTO "https://raw.githubusercontent.com/cyberbotics/webots/R2025a/projects/vehicles/protos/toyota/ToyotaPrius.proto"
EXTERNPROTO "../protos/ParkingLines.proto"

WorldInfo {
}
Viewpoint {
  orientation -0.07265647652428918 0.001401763949226753 0.9973560404774747 3.1139693238113164
  position 59.42410059771067 1.0405161336835975 2.175281561070065
}
TexturedBackground {
}
TexturedBackgroundLight {
}
RectangleArena {
  translation 85.4162 -5.0713 -0.1
  rotation 0 0 1 0.0261799
  floorSize 200 200
  floorAppearance Asphalt {
  }
}
Robot {
  translation 9.07999 13.2888 0.1
  children [
    Solid {
      translation 40.7027 -11.6345 -1.06582e-14
      rotation 0 0 1 1.5708
      children [
        HingeJoint {
          jointParameters HingeJointParameters {
            position 1.628449907170302e-05
            axis 0 1 0
            anchor 0 0 1
          }
          device [
            RotationalMotor {
              name "barrier_motor_entry"
              maxTorque 500
            }
          ]
          endPoint Solid {
            translation 0.829999999889984 1.3322699999999935e-15 0.999986486520744
            rotation 0 1 0 1.6284508194236965e-05
            children [
              Pose {
                translation 0.5 0 0
                children [
                  Shape {
                    geometry Box {
                      size 3 0.08 0.08
                    }
                  }
                ]
              }
            ]
            name "barrier_arm_entry"
            physics Physics {
            }
          }
        }
        Shape {
          geometry Cylinder {
            height 3
            radius 0.5
          }
        }
      ]
      name "barrier_pole_entry"
    }
  ]
  name "barrier_entry"
  controller "barrier_controller_entry"
}
ParkingLines {
  translation 12 12 0
}
ParkingLines {
  translation 12 -12 0
}
ParkingLines {
  translation 0 -12 0
}
ParkingLines {
  translation 12 0 0
}
ParkingLines {
  translation 12 0 0
}
ParkingLines {
  translation 0 12 0
}
ParkingLines {
}
Robot {
  translation 9.03162 11.9418 5.32907e-15
  children [
    Solid {
      translation 40.7027 -11.6345 -1.06582e-14
      rotation 0 0 1 -1.5707953071795862
      children [
        HingeJoint {
          jointParameters HingeJointParameters {
            position 8.142301658192814e-06
            axis 0 1 0
            anchor 0 0 1
          }
          device [
            RotationalMotor {
              name "barrier_motor_exit"
              maxTorque 500
            }
          ]
          endPoint Solid {
            translation 0.8299999999725063 1.3322699999999935e-15 0.9999932445445967
            rotation 0 0.9999999999999999 0 8.14230863822956e-06
            children [
              Pose {
                translation 0.5 0 0
                children [
                  Shape {
                    geometry Box {
                      size 3 0.08 0.08
                    }
                  }
                ]
              }
            ]
            name "barrier_arm_exit"
            physics Physics {
            }
          }
        }
        Shape {
          geometry Cylinder {
            height 3
            radius 0.5
          }
        }
      ]
      name "barrier_pole_exit"
    }
  ]
  name "barrier_exit"
  controller "barrier_controller_exit"
  controllerArgs [
    ""
  ]
}
DEF PARKING_SPOT Pose {
  translation 13.14 -7.04 0.1
}
ToyotaPrius {
  translation 53.5 1.65 -0.173432
  rotation 0.015123266213618024 -0.0007448634262533459 0.9998853594275237 3.043168159562019
  name "Car Pay-in"
  controller "vehicle_controller"
  supervisor TRUE
  sensorsSlotCenter [
    GPS {
    }
  ]
}
